<?xml version="1.0"?>
<robot name="rover" xmlns:xacro="http://ros.org/wiki/xacro">
  <!-- Define robot constants -->
  <xacro:property name="base_width" value="0.24"/>
  <xacro:property name="base_length" value="0.31"/>
  <xacro:property name="base_height" value="0.07"/>

  <xacro:property name="wheel_radius" value="0.0762"/>
  <xacro:property name="wheel_width" value="0.05552"/>
  <xacro:property name="wheel_ygap" value="0.04776"/>
  <xacro:property name="wheel_zoff" value="0.005"/>
  <xacro:property name="wheel_xoff" value="0.105"/>

  <!-- Robot Base -->
  <link name="base_link">
    <visual>
      <geometry>
        <box size="${base_length} ${base_width} ${base_height}"/>
      </geometry>
      <material name="Black">
        <color rgba="0 0 0 1.0"/>
      </material>
    </visual>
  </link>

  <!-- Robot Footprint -->
  <link name="base_footprint"/>

  <joint name="base_joint" type="fixed">
    <parent link="base_link"/>
    <child link="base_footprint"/>
    <origin xyz="0.0 0.0 ${-(wheel_radius+wheel_zoff)}" rpy="0 0 0"/>
  </joint>

  <!-- Wheels -->
  <xacro:macro name="wheel" params="prefix x_reflect y_reflect">
    <link name="${prefix}_link">
      <visual>
        <origin xyz="0 0 0" rpy="${pi/2} 0 0"/>
        <geometry>
            <cylinder radius="${wheel_radius}" length="${wheel_width}"/>
        </geometry>
        <material name="Gray">
          <color rgba="0.5 0.5 0.5 1.0"/>
        </material>
      </visual>
    </link>

    <joint name="${prefix}_joint" type="continuous">
      <parent link="base_link"/>
      <child link="${prefix}_link"/>
      <origin xyz="${x_reflect*wheel_xoff} ${y_reflect*(base_width/2+wheel_ygap)} ${wheel_zoff}" rpy="0 0 0"/>
      <axis xyz="0 1 0"/>
    </joint>
  </xacro:macro>
  
  <!-- LiDAR -->
  <link name="laser"/>

  <joint name="base_link_to_laser" type="fixed">
    <parent link="base_link"/>
    <child link="laser"/>
    <origin xyz="0.2 0.0 0.1" rpy="0 0 0"/> 
  </joint>

  <link name="camera_link"/>

  <!-- Static Transform from base_link to camera_link -->
  <joint name="base_link_to_camera_link" type="fixed">
    <parent link="base_link"/>
    <child link="camera_link"/>
    <origin xyz="0.2 0.0 0.1" rpy="0 0 0"/>  <!-- adjust xyz/rpy as needed -->
  </joint>

  <link name="camera_imu_frame"/>

  <joint name="camera_link_to_camera_imu_frame" type="fixed">
    <parent link="camera_link"/>
    <child link="camera_imu_frame"/>
    <origin xyz="0 0 0" rpy="0 0 0"/>
  </joint>

  <link name="camera_imu_optical_frame"/>
  
  <joint name="camera_imu_to_camera_imu_optical" type="fixed">
    <parent link="camera_imu_frame"/>
    <child link="camera_imu_optical_frame"/>
    <origin xyz="0 0 0" rpy="-1.5707963 0 -1.5707963"/>
  </joint>


  <xacro:wheel prefix="front_left_whl" x_reflect="1" y_reflect="1" />
  <xacro:wheel prefix="front_right_whl" x_reflect="1" y_reflect="-1" />
  <xacro:wheel prefix="back_left_whl" x_reflect="-1" y_reflect="1" />
  <xacro:wheel prefix="back_right_whl" x_reflect="-1" y_reflect="-1" />

</robot>