<?xml version="1.0" ?>
<sdf version="0" xmlns:xacro="http://ros.org/wiki/xacro">
    <model name='rover' canonical_link='base_link'>

        <!-- Define robot constants -->
        <xacro:property name="base_width" value="0.24"/>
        <xacro:property name="base_length" value="0.31"/>
        <xacro:property name="base_height" value="0.07"/>

        <xacro:property name="wheel_radius" value="0.0762"/>
        <xacro:property name="wheel_width" value="0.05552"/>
        <xacro:property name="wheel_ygap" value="0.04776"/>
        <xacro:property name="wheel_zoff" value="0.005"/>
        <xacro:property name="wheel_xoff" value="0.105"/>

        <!-- Define some commonly used inertial properties  -->
        <xacro:macro name="box_inertia" params="m w h d">
        <inertial>
            <pose>0 0 0 ${pi/2} 0 ${pi/2}</pose>
            <mass>${m}</mass>
            <inertia>
            <ixx>${(m/12) * (h*h + d*d)}</ixx>
            <ixy>0.0</ixy>
            <ixz>0.0</ixz>
            <iyy>${(m/12) * (w*w + d*d)}</iyy>
            <iyz>0.0</iyz>
            <izz>${(m/12) * (w*w + h*h)}</izz>
            </inertia>
        </inertial>
        </xacro:macro>

        <xacro:macro name="cylinder_inertia" params="m r h">
        <inertial>
            <pose>0 0 0 ${pi/2} 0 0</pose>
            <mass>${m}</mass>
            <inertia>
            <ixx>${(m/12) * (3*r*r + h*h)}</ixx>
            <ixy>0.0</ixy>
            <ixz>0.0</ixz>
            <iyy>${(m/12) * (3*r*r + h*h)}</iyy>
            <iyz>0.0</iyz>
            <izz>${(m/2) * (r*r)}</izz>
            </inertia>
        </inertial>
        </xacro:macro>


        <!-- Robot Base -->
        <link name='base_link'>
            <visual>
                <geometry>
                    <box size="${base_length} ${base_width} ${base_height}"/>
                </geometry>
                <material name="Black">
                    <color rgba="0 0 0 1.0"/>
                </material>
            </visual>

            <collision name="base_link_collision">
                <geometry>
                    <box><size>
                        ${base_length} ${base_width} ${base_height}
                    </size></box>
                </geometry>
            </collision>
        </link>

        <!-- Robot Footprint -->
        <link name="base_footprint">
            <pose relative_to="base_joint"/>
            <xacro:box_inertia m="15" w="${base_width}" d="${base_length}" h="${base_height}"/>
        </link>

        <joint name="base_joint" type="fixed">
            <parent link="base_link"/>
            <child link="base_footprint"/>
            <origin xyz="0.0 0.0 ${-(wheel_radius+wheel_zoff)}" rpy="0 0 0"/>
        </joint>

        <!-- Wheels -->
        <xacro:macro name="wheel" params="prefix x_reflect y_reflect">
            <link name="${prefix}_link">
                <visual>
                    <origin xyz="0 0 0" rpy="${pi/2} 0 0"/>
                    <geometry>
                        <cylinder radius="${wheel_radius}" length="${wheel_width}"/>
                    </geometry>
                    <material name="Gray">
                        <color rgba="0.5 0.5 0.5 1.0"/>
                    </material>
                </visual>


                <collision name="${prefix}_link_collision">
                    <pose relative_to="${prefix}_link">0 0 0 ${pi/2} 0 0</pose>
                    <geometry>
                        <cylinder radius="${wheel_radius}" length="${wheel_width}"/>
                    </geometry>
                </collision>

                <xacro:sphere_inertia m="0.5" r="${(wheel_radius+wheel_zoff-(base_height/2))}"/>
            </link>

            <joint name="${prefix}_joint" type="continuous">
                <parent link="base_link"/>
                <child link="${prefix}_link"/>
                <origin xyz="${x_reflect*wheel_xoff} ${y_reflect*(base_width/2+wheel_ygap)} ${wheel_zoff}" rpy="0 0 0"/>
                <axis xyz="0 1 0"/>
            </joint>
        </xacro:macro>
     </model>
</sdf>